<?xml version="1.0"?>
<robot name="xarm7_robot">
  <!-- Materials -->
  <material name="Black">
    <color rgba="0.0 0.0 0.0 1.0"/>
  </material>

  <material name="Red">
    <color rgba="0.8 0.0 0.0 1.0"/>
  </material>

  <material name="White">
    <color rgba="1.0 1.0 1.0 1.0"/>
  </material>

  <material name="Silver">
    <color rgba="0.753 0.753 0.753 1.0"/>
  </material>

  <!-- Base Link -->
  <link name="link_base">
    <inertial>
      <origin xyz="-0.021131 -0.0016302 0.056488" rpy="0 0 0"/>
      <mass value="0.88556"/>
      <inertia
        ixx="0.0030595" ixy="0.00012259" ixz="-0.00062705"
        iyy="0.0037783" iyz="0.00027023" izz="0.0020125"/>
    </inertial>
    <visual>
      <origin xyz="0 0 0" rpy="0 0 0"/>
      <geometry>
        <mesh filename="meshes/link_base.stl"/>
      </geometry>
      <material name="White"/>
    </visual>
    <collision>
      <origin xyz="0 0 0" rpy="0 0 0"/>
      <geometry>
        <mesh filename="meshes/link_base.stl"/>
      </geometry>
    </collision>
  </link>

  <!-- Link 1 -->
  <link name="link1">
    <inertial>
      <origin xyz="-0.0042142 0.02821 -0.0087788" rpy="0 0 0"/>
      <mass value="0.42603"/>
      <inertia
        ixx="0.0014243" ixy="3.9946E-05" ixz="4.7078E-06"
        iyy="0.00123" iyz="-0.00026073" izz="0.00099229"/>
    </inertial>
    <visual>
      <origin xyz="0 0 0" rpy="0 0 0"/>
      <geometry>
        <mesh filename="meshes/link1.stl"/>
      </geometry>
      <material name="White"/>
    </visual>
    <collision>
      <origin xyz="0 0 0" rpy="0 0 0"/>
      <geometry>
        <mesh filename="meshes/link1.stl"/>
      </geometry>
    </collision>
  </link>

  <!-- Joint 1 -->
  <joint name="joint1" type="revolute">
    <origin xyz="0 0 0.267" rpy="0 0 0"/>
    <parent link="link_base"/>
    <child link="link1"/>
    <axis xyz="0 0 1"/>
    <limit lower="-6.28318530718" upper="6.28318530718" effort="50" velocity="3.14"/>
    <dynamics damping="10" friction="1"/>
  </joint>

  <!-- Link 2 -->
  <link name="link2">
    <inertial>
      <origin xyz="-3.3178E-05 -0.12849 0.026337" rpy="0 0 0"/>
      <mass value="0.56095"/>
      <inertia
        ixx="0.0031915" ixy="3.0892E-06" ixz="2.8729E-06"
        iyy="0.0017468" iyz="-0.0010241" izz="0.00235"/>
    </inertial>
    <visual>
      <origin xyz="0 0 0" rpy="0 0 0"/>
      <geometry>
        <mesh filename="meshes/link2.stl"/>
      </geometry>
      <material name="White"/>
    </visual>
    <collision>
      <origin xyz="0 0 0" rpy="0 0 0"/>
      <geometry>
        <mesh filename="meshes/link2.stl"/>
      </geometry>
    </collision>
  </link>

  <!-- Joint 2 -->
  <joint name="joint2" type="revolute">
    <origin xyz="0 0 0" rpy="-1.5708 -0.7 0"/>
    <parent link="link1"/>
    <child link="link2"/>
    <axis xyz="0 0 1"/>
    <limit lower="-2.059" upper="2.0944" effort="50" velocity="3.14"/>
    <dynamics damping="10" friction="1"/>
  </joint>

  <!-- Link 3 -->
  <link name="link3">
    <inertial>
      <origin xyz="0.04223 -0.023258 -0.0096674" rpy="0 0 0"/>
      <mass value="0.44463"/>
      <inertia
        ixx="0.0011454" ixy="0.0001654" ixz="-0.0001951"
        iyy="0.0010503" iyz="0.00012027" izz="0.0011083"/>
    </inertial>
    <visual>
      <origin xyz="0 0 0" rpy="0 0 0"/>
      <geometry>
        <mesh filename="meshes/link3.stl"/>
      </geometry>
      <material name="White"/>
    </visual>
    <collision>
      <origin xyz="0 0 0" rpy="0 0 0"/>
      <geometry>
        <mesh filename="meshes/link3.stl"/>
      </geometry>
    </collision>
  </link>

  <!-- Joint 3 -->
  <joint name="joint3" type="revolute">
    <origin xyz="0 -0.293 0" rpy="1.5708 0 0"/>
    <parent link="link2"/>
    <child link="link3"/>
    <axis xyz="0 0 1"/>
    <limit lower="-6.28318530718" upper="6.28318530718" effort="30" velocity="3.14"/>
    <dynamics damping="5" friction="1"/>
  </joint>

  <!-- Link 4 -->
  <link name="link4">
    <inertial>
      <origin xyz="0.067148 -0.10732 0.024479" rpy="0 0 0"/>
      <mass value="0.52387"/>
      <inertia
        ixx="0.0026033" ixy="0.00053379" ixz="0.00036314"
        iyy="0.0017649" iyz="-0.00083253" izz="0.0022431"/>
    </inertial>
    <visual>
      <origin xyz="0 0 0" rpy="0 0 0"/>
      <geometry>
        <mesh filename="meshes/link4.stl"/>
      </geometry>
      <material name="White"/>
    </visual>
    <collision>
      <origin xyz="0 0 0" rpy="0 0 0"/>
      <geometry>
        <mesh filename="meshes/link4.stl"/>
      </geometry>
    </collision>
  </link>

  <!-- Joint 4 -->
  <joint name="joint4" type="revolute">
    <origin xyz="0.0525 0 0" rpy="1.5708 0 0"/>
    <parent link="link3"/>
    <child link="link4"/>
    <axis xyz="0 0 1"/>
    <limit lower="-0.19198" upper="3.927" effort="30" velocity="3.14"/>
    <dynamics damping="5" friction="1"/>
  </joint>

  <!-- Link 5 -->
  <link name="link5">
    <inertial>
      <origin xyz="-0.00023397 0.036705 -0.080064" rpy="0 0 0"/>
      <mass value="0.18554"/>
      <inertia
        ixx="0.00099549" ixy="8.9957E-07" ixz="8.5285E-07"
        iyy="0.0008853" iyz="-0.00025682" izz="0.00035048"/>
    </inertial>
    <visual>
      <origin xyz="0 0 0" rpy="0 0 0"/>
      <geometry>
        <mesh filename="meshes/link5.stl"/>
      </geometry>
      <material name="White"/>
    </visual>
    <collision>
      <origin xyz="0 0 0" rpy="0 0 0"/>
      <geometry>
        <mesh filename="meshes/link5.stl"/>
      </geometry>
    </collision>
  </link>

  <!-- Joint 5 -->
  <joint name="joint5" type="revolute">
    <origin xyz="0.0775 -0.3425 0" rpy="1.5708 0 0"/>
    <parent link="link4"/>
    <child link="link5"/>
    <axis xyz="0 0 1"/>
    <limit lower="-6.28318530718" upper="6.28318530718" effort="30" velocity="3.14"/>
    <dynamics damping="5" friction="1"/>
  </joint>

  <!-- Link 6 -->
  <link name="link6">
    <inertial>
      <origin xyz="0.058911 0.028469 0.0068428" rpy="0 0 0"/>
      <mass value="0.31344"/>
      <inertia
        ixx="0.00052034" ixy="-0.00014989" ixz="0.00011658"
        iyy="0.00067968" iyz="6.116E-05" izz="0.00078345"/>
    </inertial>
    <visual>
      <origin xyz="0 0 0" rpy="0 0 0"/>
      <geometry>
        <mesh filename="meshes/link6.stl"/>
      </geometry>
      <material name="White"/>
    </visual>
    <collision>
      <origin xyz="0 0 0" rpy="0 0 0"/>
      <geometry>
        <mesh filename="meshes/link6.stl"/>
      </geometry>
    </collision>
  </link>

  <!-- Joint 6 -->
  <joint name="joint6" type="revolute">
    <origin xyz="0 0 0" rpy="1.5708 -0.64 0"/>
    <parent link="link5"/>
    <child link="link6"/>
    <axis xyz="0 0 1"/>
    <limit lower="-1.69297" upper="3.14159265359" effort="20" velocity="3.14"/>
    <dynamics damping="2" friction="1"/>
  </joint>

  <!-- Link 7 -->
  <link name="link7">
    <inertial>
      <origin xyz="-1.5846E-05 -0.0046377 -0.012705" rpy="0 0 0"/>
      <mass value="0.31468"/>
      <inertia
        ixx="0.00016985" ixy="1.1102E-07" ixz="5.1075E-08"
        iyy="0.00011924" iyz="-2.1251E-06" izz="0.00026032"/>
    </inertial>
    <visual>
      <origin xyz="0 0 0" rpy="0 0 0"/>
      <geometry>
        <mesh filename="meshes/link7.stl"/>
      </geometry>
      <material name="Silver"/>
    </visual>
    <collision>
      <origin xyz="0 0 0" rpy="0 0 0"/>
      <geometry>
        <mesh filename="meshes/link7.stl"/>
      </geometry>
    </collision>
  </link>

  <!-- Joint 7 -->
  <joint name="joint7" type="revolute">
    <origin xyz="0.076 0.097 0" rpy="-1.5708 0 0"/>
    <parent link="link6"/>
    <child link="link7"/>
    <axis xyz="0 0 1"/>
    <limit lower="-6.28318530718" upper="6.28318530718" effort="20" velocity="3.14"/>
    <dynamics damping="2" friction="1"/>
  </joint>

  <!-- End Effector Link -->
  <link name="link_eef"/>

  
  <!-- End Effector Joint -->
  <joint name="joint_eef" type="fixed">
    <origin xyz="0 0 0" rpy="0 0 0"/>
    <parent link="link7"/>
    <child link="link_eef"/>
  </joint>

  <joint name="arm_gripper_joint" type="fixed">
    <origin xyz="0 0 0" rpy="0 0 0"/>
    <parent link="link_eef"/>
    <child link="xarm_gripper_base_link"/>
  </joint>

 
    <link name="xarm_gripper_base_link">
    <inertial>
      <origin xyz="-0.00065489 -0.0018497 0.048028" rpy="0 0 0"/>
      <mass value="0.54156"/>
      <inertia
        ixx="0.00047106" ixy="3.9292E-07" ixz="2.6537E-06"
        iyy="0.00033072" iyz="-1.0975E-05" izz="0.00025642"/>
    </inertial>
    <visual>
      <origin xyz="0 0 0" rpy="0 0 0"/>
      <geometry>
        <mesh filename="meshes/gripper/xarm/base_link.stl"/>
      </geometry>
      <material name="White"/>
    </visual>
    <collision>
      <origin xyz="0 0 0" rpy="0 0 0"/>
      <geometry>
        <mesh filename="meshes/gripper/xarm/base_link.stl"/>
      </geometry>
    </collision>
  </link>
  <link name="left_outer_knuckle">
    <inertial>
      <origin xyz="2.9948E-14 0.021559 0.015181" rpy="0 0 0"/>
      <mass value="0.033618"/>
      <inertia
        ixx="1.9111E-05" ixy="-1.8803E-17" ixz="-1.1002E-17"
        iyy="6.6256E-06" iyz="-7.3008E-06" izz="1.3185E-05"/>
    </inertial>
    <visual>
      <origin xyz="0 0 0" rpy="0 0 0"/>
      <geometry>
        <mesh filename="meshes/gripper/xarm/left_outer_knuckle.stl"/>
      </geometry>
      <material name="Silver"/>
    </visual>
    <collision>
      <origin xyz="0 0 0" rpy="0 0 0"/>
      <geometry>
        <mesh filename="meshes/gripper/xarm/left_outer_knuckle.stl"/>
      </geometry>
    </collision>
  </link>
  <joint name="drive_joint" type="revolute">
    <origin xyz="0 0.035 0.059098" rpy="0 0 0"/>
    <parent link="xarm_gripper_base_link"/>
    <child link="left_outer_knuckle"/>
    <axis xyz="1 0 0"/>
    <limit lower="0" upper="0.85" effort="50" velocity="2"/>
  </joint>
  <link name="left_finger">
    <inertial>
      <origin xyz="-2.4536E-14 -0.016413 0.029258" rpy="0 0 0"/>
      <mass value="0.048304"/>
      <inertia
        ixx="1.7493E-05" ixy="-4.2156E-19" ixz="6.9164E-18"
        iyy="1.7225E-05" iyz="4.6433E-06" izz="5.1466E-06"/>
    </inertial>
    <visual>
      <origin xyz="0 0 0" rpy="0 0 0"/>
      <geometry>
        <mesh filename="meshes/gripper/xarm/left_finger.stl"/>
      </geometry>
      <material name="Silver"/>
    </visual>
    <collision>
      <origin xyz="0 0 0" rpy="0 0 0"/>
      <geometry>
        <mesh filename="meshes/gripper/xarm/left_finger.stl"/>
      </geometry>
    </collision>
  </link>
  <joint name="left_finger_joint" type="revolute">
    <origin xyz="0 0.035465 0.042039" rpy="0 0 0"/>
    <parent link="left_outer_knuckle"/>
    <child link="left_finger"/>
    <axis xyz="-1 0 0"/>
    <limit lower="0" upper="0.85" effort="50" velocity="2"/>
    <mimic joint="drive_joint" multiplier="1" offset="0"/>
  </joint>
  <link name="left_inner_knuckle">
    <inertial>
      <origin xyz="1.86600784687907E-06 0.0220467847633621 0.0261334672830885" rpy="0 0 0"/>
      <mass value="0.0230125781256706"/>
      <inertia
        ixx="6.09490024271906E-06" ixy="6.06651326160071E-11" ixz="7.19102670500635E-11"
        iyy="6.01955084375188E-06" iyz="-2.75316812991721E-06" izz="5.07862004479903E-06"/>
    </inertial>
    <visual>
      <origin xyz="0 0 0" rpy="0 0 0"/>
      <geometry>
        <mesh filename="meshes/gripper/xarm/left_inner_knuckle.stl"/>
      </geometry>
      <material name="Silver"/>
    </visual>
    <collision>
      <origin xyz="0 0 0" rpy="0 0 0"/>
      <geometry>
        <mesh filename="meshes/gripper/xarm/left_inner_knuckle.stl"/>
      </geometry>
    </collision>
  </link>
  <joint name="left_inner_knuckle_joint" type="revolute">
    <origin xyz="0 0.02 0.074098" rpy="0 0 0"/>
    <parent link="xarm_gripper_base_link"/>
    <child link="left_inner_knuckle"/>
    <axis xyz="1 0 0"/>
    <limit lower="0" upper="0.85" effort="50" velocity="2"/>
    <mimic joint="drive_joint" multiplier="1" offset="0"/>
  </joint>
  <link name="right_outer_knuckle">
    <inertial>
      <origin xyz="-3.1669E-14 -0.021559 0.015181" rpy="0 0 0"/>
      <mass value="0.033618"/>
      <inertia
        ixx="1.9111E-05" ixy="-1.8789E-17" ixz="1.0986E-17"
        iyy="6.6256E-06" iyz="7.3008E-06" izz="1.3185E-05"/>
    </inertial>
    <visual>
      <origin xyz="0 0 0" rpy="0 0 0"/>
      <geometry>
        <mesh filename="meshes/gripper/xarm/right_outer_knuckle.stl"/>
      </geometry>
      <material name="Silver"/>
    </visual>
    <collision>
      <origin xyz="0 0 0" rpy="0 0 0"/>
      <geometry>
        <mesh filename="meshes/gripper/xarm/right_outer_knuckle.stl"/>
      </geometry>
    </collision>
  </link>
  <joint name="right_outer_knuckle_joint" type="revolute">
    <origin xyz="0 -0.035 0.059098" rpy="0 0 0"/>
    <parent link="xarm_gripper_base_link"/>
    <child link="right_outer_knuckle"/>
    <axis xyz="-1 0 0"/>
    <limit lower="0" upper="0.85" effort="50" velocity="2"/>
    <mimic joint="drive_joint" multiplier="1" offset="0"/>
  </joint>
  <link name="right_finger">
    <inertial>
      <origin xyz="2.5618E-14 0.016413 0.029258" rpy="0 0 0"/>
      <mass value="0.048304"/>
      <inertia
        ixx="1.7493E-05" ixy="-5.0014E-19" ixz="-7.5079E-18"
        iyy="1.7225E-05" iyz="-4.6435E-06" izz="5.1466E-06"/>
    </inertial>
    <visual>
      <origin xyz="0 0 0" rpy="0 0 0"/>
      <geometry>
        <mesh filename="meshes/gripper/xarm/right_finger.stl"/>
      </geometry>
      <material name="Silver"/>
    </visual>
    <collision>
      <origin xyz="0 0 0" rpy="0 0 0"/>
      <geometry>
        <mesh filename="meshes/gripper/xarm/right_finger.stl"/>
      </geometry>
    </collision>
  </link>
  <joint name="right_finger_joint" type="revolute">
    <origin xyz="0 -0.035465 0.042039" rpy="0 0 0"/>
    <parent link="right_outer_knuckle"/>
    <child link="right_finger"/>
    <axis xyz="1 0 0"/>
    <limit lower="0" upper="0.85" effort="50" velocity="2"/>
    <mimic joint="drive_joint" multiplier="1" offset="0"/>
  </joint>
  <link name="right_inner_knuckle">
    <inertial>
      <origin xyz="1.866E-06 -0.022047 0.026133" rpy="0 0 0"/>
      <mass value="0.023013"/>
      <inertia
        ixx="6.0949E-06" ixy="-6.0665E-11" ixz="7.191E-11"
        iyy="6.0197E-06" iyz="2.7531E-06" izz="5.0784E-06"/>
    </inertial>
    <visual>
      <origin xyz="0 0 0" rpy="0 0 0"/>
      <geometry>
        <mesh filename="meshes/gripper/xarm/right_inner_knuckle.stl"/>
      </geometry>
      <material name="Silver"/>
    </visual>
    <collision>
      <origin xyz="0 0 0" rpy="0 0 0"/>
      <geometry>
        <mesh filename="meshes/gripper/xarm/right_inner_knuckle.stl"/>
      </geometry>
    </collision>
  </link>
  <joint name="right_inner_knuckle_joint" type="revolute">
    <origin xyz="0 -0.02 0.074098" rpy="0 0 0"/>
    <parent link="xarm_gripper_base_link"/>
    <child link="right_inner_knuckle"/>
    <axis xyz="-1 0 0"/>
    <limit lower="0" upper="0.85" effort="50" velocity="2"/>
    <mimic joint="drive_joint" multiplier="1" offset="0"/>
  </joint>
  <link name="link_tcp"/>
  <joint name="joint_tcp" type="fixed">
    <origin xyz="0 0 0.172" rpy="0 0 0"/>
    <parent link="xarm_gripper_base_link"/>
    <child link="link_tcp"/>
  </joint>

    
    
</robot>